Workbook

Sheet crecimientos
A2: 2025 | B2: Global 2025 | C2: Global 2026 | D2: Vta Ecom 2025 | E2: Venta Ecom 2026 | F2: Digital 2025 | G2: Digital 2026 | H2: MKP 2025 | I2: MKP 2026 | J2: 2026 | K2: Venta Meta 2026 | L2: Meta Digital | M2: Meta MKPlace | N2: Web + APP 2025 | O2: Web + APP 2026 | P2: Afiliados 2025 | Q2: Afiliados 2026 | R2: TMK 2025 | S2: TMK 2026 | T2: WA 2025 | U2: WA 2026 | V2: Ent. en Tienda 2025 | W2: Ent. en Tienda 2026 | X2: Meli Drop 2025 | Y2: Meli Drop 2026 | Z2: Meli Full 2025 | AA2: Meli Full 2026 | AB2: Amazon Drop 2025 | AC2: Amazon Drop 2026 | AD2: Amazon Full 2025 | AE2: Amazon Full 2026 | AF2: TikTok 2025 | AG2: TikTok 2026 | AH2: Shein 2025 | AI2: Shein 2026 | AJ2: MELI 2025 | AK2: MELI2026 | AL2: AMZ 2025 | AM2: AMZ 2026 | AN2: 2026 | AO2: Global | AP2: Ecomm | AQ2: Digital | AR2: MKP | AS2: Web + APP | AT2: Afiliados | AU2: TMK | AV2: WA | AW2: Ent. en Tienda | AX2: Meli Drop | AY2: Meli Full | AZ2: MELI | BA2: Amazon Drop | BB2: Amazon Full | BC2: AMAZON | BD2: TikTok | BE2: Shein
A3: 45659 | B3: 35585285 | C3: 1767787 | D3: 3530236.3 | E3: 1767692 | F3: =SUM(N3,P3,R3,T3,V3) -> 2657177.3 | G3: =SUM(O3,Q3,S3,U3,W3) -> 1137078 | H3: =SUM(X3,Z3,AB3,AD3,AF3,AH3) -> 873059 | I3: =SUM(Y3,AA3,AC3,AE3,AG3,AI3) -> 630614 | J3: 46023 | K3: -36578.828 | L3: -91461.011 | M3: 54882.183 | N3: 2533552 | O3: 1117875 | P3: 48254.31 | Q3: 17319 | R3: 21696 | S3: 0 | T3: 5984 | U3: 1884 | V3: 47691 | W3: 0 | X3: 671816 | Y3: 511381 | Z3: 116771 | AA3: 78269 | AB3: 84472 | AC3: 31357 | AD3: 0 | AE3: 7591 | AF3: 0 | AG3: 2016 | AH3: 0 | AI3: 0 | AJ3: =X3+Z3 -> 788587 | AK3: =Y3+AA3 -> 589650 | AL3: =AD3+AB3 -> 84472 | AM3: =AE3+AC3 -> 38948 | AN3: 46023 | AO3: =C3/B3-1 -> -0.95032253 | AP3: =E3/D3-1 -> -0.49927091 | AQ3: =G3/F3-1 -> -0.57207297 | AR3: =I3/H3-1 -> -0.27769601 | AS3: =O3/N3-1 -> -0.55877164 | AT3: =Q3/P3-1 -> -0.64108906 | AU3: =S3/R3-1 -> -1 | AV3: =U3/T3-1 -> -0.68516043 | AW3: =W3/V3-1 -> -1 | AX3: =Y3/X3-1 -> -0.23880795 | AY3: =AA3/Z3-1 -> -0.32972228 | AZ3: =AK3/AJ3-1 -> -0.2522702 | BA3: =AC3/AB3-1 -> -0.62878824 | BB3: =AE3/AD3-1 -> #DIV/0! | BC3: =AM3/AL3-1 -> -0.53892414 | BD3: =AG3/AF3-1 -> #DIV/0! | BE3: =AI3/AH3-1 -> #DIV/0!
A4: 45660 | B4: 45059441 | C4: 37878399 | D4: 2122251.3 | E4: 3057411 | F4: =SUM(N4,P4,R4,T4,V4) -> 1350420.3 | G4: =SUM(O4,Q4,S4,U4,W4) -> 1978374 | H4: =SUM(X4,Z4,AB4,AD4,AF4,AH4) -> 771831 | I4: =SUM(Y4,AA4,AC4,AE4,AG4,AI4) -> 1079037 | J4: 46024 | K4: 4512263.3 | L4: 3388096 | M4: 1124167.3 | N4: 1249824 | O4: 1824628 | P4: 33610.345 | Q4: 32072 | R4: 21922 | S4: 15461 | T4: 4267 | U4: 5339 | V4: 40797 | W4: 100874 | X4: 650641 | Y4: 906403 | Z4: 73651 | AA4: 134485 | AB4: 47539 | AC4: 28403 | AD4: 0 | AE4: 8334 | AF4: 0 | AG4: 1412 | AH4: 0 | AI4: 0 | AJ4: =X4+Z4 -> 724292 | AK4: =Y4+AA4 -> 1040888 | AL4: =AD4+AB4 -> 47539 | AM4: =AE4+AC4 -> 36737 | AN4: 46024 | AO4: =C4/B4-1 -> -0.1593682 | AP4: =E4/D4-1 -> 0.4406451 | AQ4: =G4/F4-1 -> 0.46500607 | AR4: =I4/H4-1 -> 0.39802236 | AS4: =O4/N4-1 -> 0.45990796 | AT4: =Q4/P4-1 -> -0.045769981 | AU4: =S4/R4-1 -> -0.29472676 | AV4: =U4/T4-1 -> 0.25123037 | AW4: =W4/V4-1 -> 1.4725838 | AX4: =Y4/X4-1 -> 0.39309235 | AY4: =AA4/Z4-1 -> 0.82597657 | AZ4: =AK4/AJ4-1 -> 0.437111 | BA4: =AC4/AB4-1 -> -0.40253266 | BB4: =AE4/AD4-1 -> #DIV/0! | BC4: =AM4/AL4-1 -> -0.22722396 | BD4: =AG4/AF4-1 -> #DIV/0! | BE4: =AI4/AH4-1 -> #DIV/0!
A5: 45661 | B5: 52763562 | C5: 45280774 | D5: 1311867 | E5: 2619534 | F5: =SUM(N5,P5,R5,T5,V5) -> 915080.97 | G5: =SUM(O5,Q5,S5,U5,W5) -> 1941567 | H5: =SUM(X5,Z5,AB5,AD5,AF5,AH5) -> 396786 | I5: =SUM(Y5,AA5,AC5,AE5,AG5,AI5) -> 677967 | J5: 46025 | K5: 2715709.2 | L5: 1721885 | M5: 993824.24 | N5: 805491 | O5: 1844500 | P5: 33443.966 | Q5: 30385 | R5: -972 | S5: 4998 | T5: 125 | U5: 903 | V5: 76993 | W5: 60781 | X5: 272764 | Y5: 517553 | Z5: 79911 | AA5: 118746 | AB5: 44111 | AC5: 27889 | AD5: 0 | AE5: 13091 | AF5: 0 | AG5: 688 | AH5: 0 | AI5: 0 | AJ5: =X5+Z5 -> 352675 | AK5: =Y5+AA5 -> 636299 | AL5: =AD5+AB5 -> 44111 | AM5: =AE5+AC5 -> 40980 | AN5: 46025 | AO5: =C5/B5-1 -> -0.14181734 | AP5: =E5/D5-1 -> 0.99679851 | AQ5: =G5/F5-1 -> 1.1217434 | AR5: =I5/H5-1 -> 0.70864647 | AS5: =O5/N5-1 -> 1.2899076 | AT5: =Q5/P5-1 -> -0.091465395 | AU5: =S5/R5-1 -> -6.1419753 | AV5: =U5/T5-1 -> 6.224 | AW5: =W5/V5-1 -> -0.2105646 | AX5: =Y5/X5-1 -> 0.89743881 | AY5: =AA5/Z5-1 -> 0.48597815 | AZ5: =AK5/AJ5-1 -> 0.80420784 | BA5: =AC5/AB5-1 -> -0.36775407 | BB5: =AE5/AD5-1 -> #DIV/0! | BC5: =AM5/AL5-1 -> -0.070980028 | BD5: =AG5/AF5-1 -> #DIV/0! | BE5: =AI5/AH5-1 -> #DIV/0!
A6: 45662 | B6: 49768856 | C6: 49319936 | D6: 1824121.7 | E6: 2295830 | F6: =SUM(N6,P6,R6,T6,V6) -> 1383885.7 | G6: =SUM(O6,Q6,S6,U6,W6) -> 1968323 | H6: =SUM(X6,Z6,AB6,AD6,AF6,AH6) -> 440236 | I6: =SUM(Y6,AA6,AC6,AE6,AG6,AI6) -> 327507 | J6: 46026 | K6: 1677704.5 | L6: 1166795.4 | M6: 510909.18 | N6: 1228466 | O6: 1894237 | P6: 26220.69 | Q6: 35794 | R6: 6650 | S6: 2820 | T6: 4220 | U6: 1256 | V6: 118329 | W6: 34216 | X6: 311434 | Y6: 181111 | Z6: 74826 | AA6: 111132 | AB6: 53976 | AC6: 24171 | AD6: 0 | AE6: 11093 | AF6: 0 | AG6: 0 | AH6: 0 | AI6: 0 | AJ6: =X6+Z6 -> 386260 | AK6: =Y6+AA6 -> 292243 | AL6: =AD6+AB6 -> 53976 | AM6: =AE6+AC6 -> 35264 | AN6: 46026 | AO6: =C6/B6-1 -> -0.0090200988 | AP6: =E6/D6-1 -> 0.25859476 | AQ6: =G6/F6-1 -> 0.42231617 | AR6: =I6/H6-1 -> -0.25606493 | AS6: =O6/N6-1 -> 0.54195314 | AT6: =Q6/P6-1 -> 0.36510521 | AU6: =S6/R6-1 -> -0.57593985 | AV6: =U6/T6-1 -> -0.70236967 | AW6: =W6/V6-1 -> -0.71084012 | AX6: =Y6/X6-1 -> -0.41846105 | AY6: =AA6/Z6-1 -> 0.48520568 | AZ6: =AK6/AJ6-1 -> -0.24340341 | BA6: =AC6/AB6-1 -> -0.55218986 | BB6: =AE6/AD6-1 -> #DIV/0! | BC6: =AM6/AL6-1 -> -0.3466726 | BD6: =AG6/AF6-1 -> #DIV/0! | BE6: =AI6/AH6-1 -> #DIV/0!
A7: 45663 | B7: 22835293 | C7: 42820052 | D7: 3136399 | E7: 3582433 | F7: =SUM(N7,P7,R7,T7,V7) -> 2260858 | G7: =SUM(O7,Q7,S7,U7,W7) -> 2378747 | H7: =SUM(X7,Z7,AB7,AD7,AF7,AH7) -> 875541 | I7: =SUM(Y7,AA7,AC7,AE7,AG7,AI7) -> 1203686 | J7: 46027 | K7: 2331412 | L7: 1764555.8 | M7: 566856.23 | N7: 2147376 | O7: 2243868 | P7: 18700 | Q7: 29134 | R7: 36331 | S7: 10063 | T7: -500 | U7: 4612 | V7: 58951 | W7: 91070 | X7: 714238 | Y7: 1061982 | Z7: 83712 | AA7: 81808 | AB7: 77591 | AC7: 39071 | AD7: 0 | AE7: 9717 | AF7: 0 | AG7: 11108 | AH7: 0 | AI7: 0 | AJ7: =X7+Z7 -> 797950 | AK7: =Y7+AA7 -> 1143790 | AL7: =AD7+AB7 -> 77591 | AM7: =AE7+AC7 -> 48788 | AN7: 46027 | AO7: =C7/B7-1 -> 0.87516981 | AP7: =E7/D7-1 -> 0.14221214 | AQ7: =G7/F7-1 -> 0.052143478 | AR7: =I7/H7-1 -> 0.37479113 | AS7: =O7/N7-1 -> 0.044934841 | AT7: =Q7/P7-1 -> 0.55796791 | AU7: =S7/R7-1 -> -0.72301891 | AV7: =U7/T7-1 -> -10.224 | AW7: =W7/V7-1 -> 0.54484233 | AX7: =Y7/X7-1 -> 0.48687412 | AY7: =AA7/Z7-1 -> -0.022744648 | AZ7: =AK7/AJ7-1 -> 0.43341061 | BA7: =AC7/AB7-1 -> -0.49644933 | BB7: =AE7/AD7-1 -> #DIV/0! | BC7: =AM7/AL7-1 -> -0.37121573 | BD7: =AG7/AF7-1 -> #DIV/0! | BE7: =AI7/AH7-1 -> #DIV/0!
A8: 45664 | B8: 23697613 | C8: 22329279 | D8: 2922246.1 | E8: 3328582 | F8: =SUM(N8,P8,R8,T8,V8) -> 2574526.1 | G8: =SUM(O8,Q8,S8,U8,W8) -> 2530631 | H8: =SUM(X8,Z8,AB8,AD8,AF8,AH8) -> 347720 | I8: =SUM(Y8,AA8,AC8,AE8,AG8,AI8) -> 797951 | J8: 46028 | K8: 4010123 | L8: 2882759.8 | M8: 1127363.2 | N8: 2444768 | O8: 2374462 | P8: 20049.138 | Q8: 21733 | R8: 54064 | S8: 67853 | T8: -344 | U8: -114 | V8: 55989 | W8: 66697 | X8: 209116 | Y8: 650825 | Z8: 80417 | AA8: 87785 | AB8: 58187 | AC8: 32894 | AD8: 0 | AE8: 14047 | AF8: 0 | AG8: 11280 | AH8: 0 | AI8: 1120 | AJ8: =X8+Z8 -> 289533 | AK8: =Y8+AA8 -> 738610 | AL8: =AD8+AB8 -> 58187 | AM8: =AE8+AC8 -> 46941 | AN8: 46028 | AO8: =C8/B8-1 -> -0.057741427 | AP8: =E8/D8-1 -> 0.13904916 | AQ8: =G8/F8-1 -> -0.017049793 | AR8: =I8/H8-1 -> 1.294809 | AS8: =O8/N8-1 -> -0.028757739 | AT8: =Q8/P8-1 -> 0.083986757 | AU8: =S8/R8-1 -> 0.25504957 | AV8: =U8/T8-1 -> -0.66860465 | AW8: =W8/V8-1 -> 0.19125185 | AX8: =Y8/X8-1 -> 2.1122678 | AY8: =AA8/Z8-1 -> 0.091622418 | AZ8: =AK8/AJ8-1 -> 1.5510391 | BA8: =AC8/AB8-1 -> -0.43468472 | BB8: =AE8/AD8-1 -> #DIV/0! | BC8: =AM8/AL8-1 -> -0.19327341 | BD8: =AG8/AF8-1 -> #DIV/0! | BE8: =AI8/AH8-1 -> #DIV/0!
A9: 45665 | B9: 26871838 | C9: 23046004 | D9: 3244805 | E9: 3134032 | F9: =SUM(N9,P9,R9,T9,V9) -> 2599511 | G9: =SUM(O9,Q9,S9,U9,W9) -> 2550948 | H9: =SUM(X9,Z9,AB9,AD9,AF9,AH9) -> 645294 | I9: =SUM(Y9,AA9,AC9,AE9,AG9,AI9) -> 583084 | J9: 46029 | K9: 3730440.5 | L9: 3282709.7 | M9: 447730.87 | N9: 2443314 | O9: 2461726 | P9: 26275 | Q9: 24949 | R9: 56169 | S9: 16759 | T9: 3661 | U9: 5667 | V9: 70092 | W9: 41847 | X9: 538812 | Y9: 438746 | Z9: 68361 | AA9: 113224 | AB9: 38121 | AC9: 5778 | AD9: 0 | AE9: 10555 | AF9: 0 | AG9: 14781 | AH9: 0 | AI9: 0 | AJ9: =X9+Z9 -> 607173 | AK9: =Y9+AA9 -> 551970 | AL9: =AD9+AB9 -> 38121 | AM9: =AE9+AC9 -> 16333 | AN9: 46029 | AO9: =C9/B9-1 -> -0.14237337 | AP9: =E9/D9-1 -> -0.034138569 | AQ9: =G9/F9-1 -> -0.01868159 | AR9: =I9/H9-1 -> -0.096405669 | AS9: =O9/N9-1 -> 0.0075356667 | AT9: =Q9/P9-1 -> -0.050466223 | AU9: =S9/R9-1 -> -0.70163257 | AV9: =U9/T9-1 -> 0.54793772 | AW9: =W9/V9-1 -> -0.40297038 | AX9: =Y9/X9-1 -> -0.18571598 | AY9: =AA9/Z9-1 -> 0.656266 | AZ9: =AK9/AJ9-1 -> -0.090918074 | BA9: =AC9/AB9-1 -> -0.84843 | BB9: =AE9/AD9-1 -> #DIV/0! | BC9: =AM9/AL9-1 -> -0.57154849 | BD9: =AG9/AF9-1 -> #DIV/0! | BE9: =AI9/AH9-1 -> #DIV/0!
A10: 45666 | B10: 28051817 | C10: 26562197 | D10: 2520450.3 | E10: 3334996 | F10: =SUM(N10,P10,R10,T10,V10) -> 2303447.3 | G10: =SUM(O10,Q10,S10,U10,W10) -> 2731509 | H10: =SUM(X10,Z10,AB10,AD10,AF10,AH10) -> 217003 | I10: =SUM(Y10,AA10,AC10,AE10,AG10,AI10) -> 603487 | J10: 46030 | K10: 4145460 | L10: 3314567.2 | M10: 830892.8 | N10: 2184366 | O10: 2651325 | P10: 24654.31 | Q10: 23867 | R10: 59780 | S10: 32696 | T10: 2734 | U10: 1757 | V10: 31913 | W10: 21864 | X10: 73729 | Y10: 443664 | Z10: 68117 | AA10: 108455 | AB10: 75157 | AC10: 25645 | AD10: 0 | AE10: 3530 | AF10: 0 | AG10: 21246 | AH10: 0 | AI10: 947 | AJ10: =X10+Z10 -> 141846 | AK10: =Y10+AA10 -> 552119 | AL10: =AD10+AB10 -> 75157 | AM10: =AE10+AC10 -> 29175 | AN10: 46030 | AO10: =C10/B10-1 -> -0.053102443 | AP10: =E10/D10-1 -> 0.32317467 | AQ10: =G10/F10-1 -> 0.18583524 | AR10: =I10/H10-1 -> 1.7810076 | AS10: =O10/N10-1 -> 0.21377324 | AT10: =Q10/P10-1 -> -0.031933984 | AU10: =S10/R10-1 -> -0.45306122 | AV10: =U10/T10-1 -> -0.35735187 | AW10: =W10/V10-1 -> -0.31488735 | AX10: =Y10/X10-1 -> 5.0174965 | AY10: =AA10/Z10-1 -> 0.59218697 | AZ10: =AK10/AJ10-1 -> 2.8923833 | BA10: =AC10/AB10-1 -> -0.65878095 | BB10: =AE10/AD10-1 -> #DIV/0! | BC10: =AM10/AL10-1 -> -0.61181261 | BD10: =AG10/AF10-1 -> #DIV/0! | BE10: =AI10/AH10-1 -> #DIV/0!
A11: 45667 | B11: 28699623 | C11: 26952477 | D11: 2278857.6 | E11: 2577374 | F11: =SUM(N11,P11,R11,T11,V11) -> 2150898.6 | G11: =SUM(O11,Q11,S11,U11,W11) -> 2081802 | H11: =SUM(X11,Z11,AB11,AD11,AF11,AH11) -> 127959 | I11: =SUM(Y11,AA11,AC11,AE11,AG11,AI11) -> 495572 | J11: 46031 | K11: 3216481.5 | L11: 2937064.3 | M11: 279417.18 | N11: 2007643 | O11: 1967914 | P11: 26027.586 | Q11: 27977 | R11: 69118 | S11: 732 | T11: 2178 | U11: 3382 | V11: 45932 | W11: 81797 | X11: 27229 | Y11: 357183 | Z11: 63746 | AA11: 88348 | AB11: 36984 | AC11: 22372 | AD11: 0 | AE11: 11805 | AF11: 0 | AG11: 15175 | AH11: 0 | AI11: 689 | AJ11: =X11+Z11 -> 90975 | AK11: =Y11+AA11 -> 445531 | AL11: =AD11+AB11 -> 36984 | AM11: =AE11+AC11 -> 34177 | AN11: 46031 | AO11: =C11/B11-1 -> -0.060876967 | AP11: =E11/D11-1 -> 0.13099389 | AQ11: =G11/F11-1 -> -0.032124521 | AR11: =I11/H11-1 -> 2.8728968 | AS11: =O11/N11-1 -> -0.019788877 | AT11: =Q11/P11-1 -> 0.074897986 | AU11: =S11/R11-1 -> -0.98940942 | AV11: =U11/T11-1 -> 0.55280073 | AW11: =W11/V11-1 -> 0.78082818 | AX11: =Y11/X11-1 -> 12.117742 | AY11: =AA11/Z11-1 -> 0.38593794 | AZ11: =AK11/AJ11-1 -> 3.8972905 | BA11: =AC11/AB11-1 -> -0.39508977 | BB11: =AE11/AD11-1 -> #DIV/0! | BC11: =AM11/AL11-1 -> -0.075897685 | BD11: =AG11/AF11-1 -> #DIV/0! | BE11: =AI11/AH11-1 -> #DIV/0!
A12: 45668 | B12: 40105570 | C12: 35436338 | D12: 2287848.8 | E12: 2342887 | F12: =SUM(N12,P12,R12,T12,V12) -> 1735933.8 | G12: =SUM(O12,Q12,S12,U12,W12) -> 1705005 | H12: =SUM(X12,Z12,AB12,AD12,AF12,AH12) -> 551915 | I12: =SUM(Y12,AA12,AC12,AE12,AG12,AI12) -> 637882 | J12: 46032 | K12: 2907315.9 | L12: 2742553.5 | M12: 164762.44 | N12: 1623013 | O12: 1571666 | P12: 27638.793 | Q12: 27994 | R12: 37575 | S12: 71315 | T12: 943 | U12: -96 | V12: 46764 | W12: 34126 | X12: 466722 | Y12: 488987 | Z12: 44669 | AA12: 120073 | AB12: 40524 | AC12: 23228 | AD12: 0 | AE12: 6392 | AF12: 0 | AG12: -1487 | AH12: 0 | AI12: 689 | AJ12: =X12+Z12 -> 511391 | AK12: =Y12+AA12 -> 609060 | AL12: =AD12+AB12 -> 40524 | AM12: =AE12+AC12 -> 29620 | AN12: 46032 | AO12: =C12/B12-1 -> -0.11642353 | AP12: =E12/D12-1 -> 0.02405675 | AQ12: =G12/F12-1 -> -0.017816805 | AR12: =I12/H12-1 -> 0.1557613 | AS12: =O12/N12-1 -> -0.031636838 | AT12: =Q12/P12-1 -> 0.012851751 | AU12: =S12/R12-1 -> 0.89793746 | AV12: =U12/T12-1 -> -1.1018028 | AW12: =W12/V12-1 -> -0.27025062 | AX12: =Y12/X12-1 -> 0.047705058 | AY12: =AA12/Z12-1 -> 1.6880611 | AZ12: =AK12/AJ12-1 -> 0.19098694 | BA12: =AC12/AB12-1 -> -0.4268088 | BB12: =AE12/AD12-1 -> #DIV/0! | BC12: =AM12/AL12-1 -> -0.26907512 | BD12: =AG12/AF12-1 -> #DIV/0! | BE12: =AI12/AH12-1 -> #DIV/0!
A13: 45669 | B13: 41530429 | C13: 37766104 | D13: 2885246.1 | E13: 2278577 | F13: =SUM(N13,P13,R13,T13,V13) -> 2172982.1 | G13: =SUM(O13,Q13,S13,U13,W13) -> 1942100 | H13: =SUM(X13,Z13,AB13,AD13,AF13,AH13) -> 712264 | I13: =SUM(Y13,AA13,AC13,AE13,AG13,AI13) -> 336477 | J13: 46033 | K13: 2924099.1 | L13: 2213442.9 | M13: 710656.22 | N13: 2046304 | O13: 1877762 | P13: 27737.069 | Q13: 29948 | R13: 14675 | S13: -1145 | T13: -1465 | U13: 2935 | V13: 85731 | W13: 32600 | X13: 581035 | Y13: 182133 | Z13: 51721 | AA13: 111049 | AB13: 79508 | AC13: 31695 | AD13: 0 | AE13: 9041 | AF13: 0 | AG13: 1612 | AH13: 0 | AI13: 947 | AJ13: =X13+Z13 -> 632756 | AK13: =Y13+AA13 -> 293182 | AL13: =AD13+AB13 -> 79508 | AM13: =AE13+AC13 -> 40736 | AN13: 46033 | AO13: =C13/B13-1 -> -0.090640167 | AP13: =E13/D13-1 -> -0.21026597 | AQ13: =G13/F13-1 -> -0.10625125 | AR13: =I13/H13-1 -> -0.52759511 | AS13: =O13/N13-1 -> -0.082364106 | AT13: =Q13/P13-1 -> 0.079710334 | AU13: =S13/R13-1 -> -1.0780239 | AV13: =U13/T13-1 -> -3.003413 | AW13: =W13/V13-1 -> -0.61974082 | AX13: =Y13/X13-1 -> -0.68653696 | AY13: =AA13/Z13-1 -> 1.1470776 | AZ13: =AK13/AJ13-1 -> -0.53665868 | BA13: =AC13/AB13-1 -> -0.60136087 | BB13: =AE13/AD13-1 -> #DIV/0! | BC13: =AM13/AL13-1 -> -0.48764904 | BD13: =AG13/AF13-1 -> #DIV/0! | BE13: =AI13/AH13-1 -> #DIV/0!
A14: 45670 | B14: 25137619 | C14: 22002628 | D14: 4228309.2 | E14: 4170572 | F14: =SUM(N14,P14,R14,T14,V14) -> 2947735.2 | G14: =SUM(O14,Q14,S14,U14,W14) -> 2948303 | H14: =SUM(X14,Z14,AB14,AD14,AF14,AH14) -> 1280574 | I14: =SUM(Y14,AA14,AC14,AE14,AG14,AI14) -> 1222269 | J14: 46034 | K14: 3687836.2 | L14: 2770711.5 | M14: 917124.64 | N14: 2797894 | O14: 2815225 | P14: 21892.241 | Q14: 28391 | R14: 62339 | S14: 25098 | T14: 7660 | U14: 689 | V14: 57950 | W14: 78900 | X14: 1124689 | Y14: 1028542 | Z14: 34111 | AA14: 130772 | AB14: 121774 | AC14: 38266 | AD14: 0 | AE14: 9160 | AF14: 0 | AG14: 15529 | AH14: 0 | AI14: 0 | AJ14: =X14+Z14 -> 1158800 | AK14: =Y14+AA14 -> 1159314 | AL14: =AD14+AB14 -> 121774 | AM14: =AE14+AC14 -> 47426 | AN14: 46034 | AO14: =C14/B14-1 -> -0.12471312 | AP14: =E14/D14-1 -> -0.013654924 | AQ14: =G14/F14-1 -> 0.00019260842 | AR14: =I14/H14-1 -> -0.045530364 | AS14: =O14/N14-1 -> 0.0061943019 | AT14: =Q14/P14-1 -> 0.29685214 | AU14: =S14/R14-1 -> -0.59739489 | AV14: =U14/T14-1 -> -0.91005222 | AW14: =W14/V14-1 -> 0.36151855 | AX14: =Y14/X14-1 -> -0.085487633 | AY14: =AA14/Z14-1 -> 2.8337193 | AZ14: =AK14/AJ14-1 -> 0.00044356231 | BA14: =AC14/AB14-1 -> -0.68576215 | BB14: =AE14/AD14-1 -> #DIV/0! | BC14: =AM14/AL14-1 -> -0.61054084 | BD14: =AG14/AF14-1 -> #DIV/0! | BE14: =AI14/AH14-1 -> #DIV/0!
... A153: 45809 | B153: 54033676 | C153: 51664485 | D153: 4327176.6 | E153: 4126779 | F153: =SUM(N153,P153,R153,T153,V153) -> 2869134.6 | G153: =SUM(O153,Q153,S153,U153,W153) -> 2867997 | H153: =SUM(X153,Z153,AB153,AD153,AF153,AH153) -> 1458042 | I153: =SUM(Y153,AA153,AC153,AE153,AG153,AI153) -> 1258782 | J153: 46173 | K153: 5635126.4 | L153: 3688020.2 | M153: 1947106.3 | N153: 2641485 | O153: 2739282 | P153: 39671.552 | Q153: 36548 | R153: -228 | S153: 7405 | T153: 1403 | U153: 4382 | V153: 186803 | W153: 80380 | X153: 1125600 | Y153: 1043225 | Z153: 278166 | AA153: 173161 | AB153: 40863 | AC153: 23659 | AD153: 13413 | AE153: 10923 | AF153: 0 | AG153: 2086 | AH153: 0 | AI153: 5728 | AJ153: =X153+Z153 -> 1403766 | AK153: =Y153+AA153 -> 1216386 | AL153: =AD153+AB153 -> 54276 | AM153: =AE153+AC153 -> 34582 | AN153: 46173 | AO153: =C153/B153-1 -> -0.043846563 | AP153: =E153/D153-1 -> -0.046311388 | AQ153: =G153/F153-1 -> -0.00039647904 | AR153: =I153/H153-1 -> -0.13666273 | AS153: =O153/N153-1 -> 0.037023492 | AT153: =Q153/P153-1 -> -0.078735305 | AU153: =S153/R153-1 -> -33.47807 | AV153: =U153/T153-1 -> 2.1233072 | AW153: =W153/V153-1 -> -0.56970712 | AX153: =Y153/X153-1 -> -0.073183191 | AY153: =AA153/Z153-1 -> -0.37749042 | AZ153: =AK153/AJ153-1 -> -0.13348379 | BA153: =AC153/AB153-1 -> -0.42101657 | BB153: =AE153/AD153-1 -> -0.1856408 | BC153: =AM153/AL153-1 -> -0.36284914 | BD153: =AG153/AF153-1 -> #DIV/0! | BE153: =AI153/AH153-1 -> #DIV/0!
A154: 45810 | B154: 30821255 | C154: 28438618 | D154: 5295147.3 | E154: 5321760 | F154: =SUM(N154,P154,R154,T154,V154) -> 3812724.3 | G154: =SUM(O154,Q154,S154,U154,W154) -> 4223699 | H154: =SUM(X154,Z154,AB154,AD154,AF154,AH154) -> 1482423 | I154: =SUM(Y154,AA154,AC154,AE154,AG154,AI154) -> 1098061 | J154: 46174 | K154: 5628230.5 | L154: 3718237.2 | M154: 1909993.3 | N154: 3591037 | O154: 4064668 | P154: 32404.31 | Q154: 29432 | R154: 47857 | S154: 26689 | T154: 7967 | U154: 10478 | V154: 133459 | W154: 92432 | X154: 1113451 | Y154: 904974 | Z154: 281772 | AA154: 135586 | AB154: 68092 | AC154: 29579 | AD154: 19108 | AE154: 10801 | AF154: 0 | AG154: 8208 | AH154: 0 | AI154: 8913 | AJ154: =X154+Z154 -> 1395223 | AK154: =Y154+AA154 -> 1040560 | AL154: =AD154+AB154 -> 87200 | AM154: =AE154+AC154 -> 40380 | AN154: 46174 | AO154: =C154/B154-1 -> -0.077304996 | AP154: =E154/D154-1 -> 0.0050258639 | AQ154: =G154/F154-1 -> 0.1077903 | AR154: =I154/H154-1 -> -0.25927957 | AS154: =O154/N154-1 -> 0.13189254 | AT154: =Q154/P154-1 -> -0.091725771 | AU154: =S154/R154-1 -> -0.44231774 | AV154: =U154/T154-1 -> 0.3151751 | AW154: =W154/V154-1 -> -0.30741276 | AX154: =Y154/X154-1 -> -0.187235 | AY154: =AA154/Z154-1 -> -0.51880953 | AZ154: =AK154/AJ154-1 -> -0.25419807 | BA154: =AC154/AB154-1 -> -0.56560242 | BB154: =AE154/AD154-1 -> -0.43473938 | BC154: =AM154/AL154-1 -> -0.53692661 | BD154: =IFERROR(AG154/AF154-1,1) -> 1 | BE154: =IFERROR(AI154/AH154-1,1) -> 1
A155: 45811 | B155: 35443743 | C155: 32512385 | D155: 6788915.7 | E155: 5929940 | F155: =SUM(N155,P155,R155,T155,V155) -> 4893991.7 | G155: =SUM(O155,Q155,S155,U155,W155) -> 4767854 | H155: =SUM(X155,Z155,AB155,AD155,AF155,AH155) -> 1894924 | I155: =SUM(Y155,AA155,AC155,AE155,AG155,AI155) -> 1162086 | J155: 46175 | K155: 6910737.6 | L155: 4968805.9 | M155: 1941931.7 | N155: 4671193 | O155: 4572359 | P155: 32920.69 | Q155: 23766 | R155: 51815 | S155: 47963 | T155: 10260 | U155: 15476 | V155: 127803 | W155: 108290 | X155: 1389018 | Y155: 930339 | Z155: 419059 | AA155: 178091 | AB155: 74233 | AC155: 32506 | AD155: 12614 | AE155: 12255 | AF155: 0 | AG155: 4331 | AH155: 0 | AI155: 4564 | AJ155: =X155+Z155 -> 1808077 | AK155: =Y155+AA155 -> 1108430 | AL155: =AD155+AB155 -> 86847 | AM155: =AE155+AC155 -> 44761 | AN155: 46175 | AO155: =C155/B155-1 -> -0.082704527 | AP155: =E155/D155-1 -> -0.1265262 | AQ155: =G155/F155-1 -> -0.025773989 | AR155: =I155/H155-1 -> -0.38673741 | AS155: =O155/N155-1 -> -0.021158192 | AT155: =Q155/P155-1 -> -0.27808317 | AU155: =S155/R155-1 -> -0.074341407 | AV155: =U155/T155-1 -> 0.50838207 | AW155: =W155/V155-1 -> -0.1526803 | AX155: =Y155/X155-1 -> -0.33021818 | AY155: =AA155/Z155-1 -> -0.57502166 | AZ155: =AK155/AJ155-1 -> -0.38695642 | BA155: =AC155/AB155-1 -> -0.5621085 | BB155: =AE155/AD155-1 -> -0.028460441 | BC155: =AM155/AL155-1 -> -0.48459935 | BD155: =IFERROR(AG155/AF155-1,1) -> 1 | BE155: =IFERROR(AI155/AH155-1,1) -> 1
A156: 45812 | B156: 35210999 | C156: 31971655 | D156: 4673886.3 | E156: 4464670 | F156: =SUM(N156,P156,R156,T156,V156) -> 3528636.3 | G156: =SUM(O156,Q156,S156,U156,W156) -> 3739380 | H156: =SUM(X156,Z156,AB156,AD156,AF156,AH156) -> 1145250 | I156: =SUM(Y156,AA156,AC156,AE156,AG156,AI156) -> 725290 | J156: 46176 | K156: 8873325 | L156: 6391028.8 | M156: 2482296.2 | N156: 3304777 | O156: 3552563 | P156: 29785.345 | Q156: 26173 | R156: 42044 | S156: 32530 | T156: 4685 | U156: 6406 | V156: 147345 | W156: 121708 | X156: 792011 | Y156: 539970 | Z156: 301527 | AA156: 136278 | AB156: 38002 | AC156: 35037 | AD156: 13710 | AE156: 7759 | AF156: 0 | AG156: 4912 | AH156: 0 | AI156: 1334 | AJ156: =X156+Z156 -> 1093538 | AK156: =Y156+AA156 -> 676248 | AL156: =AD156+AB156 -> 51712 | AM156: =AE156+AC156 -> 42796 | AN156: 46176 | AO156: =C156/B156-1 -> -0.091998071 | AP156: =E156/D156-1 -> -0.044762822 | AQ156: =G156/F156-1 -> 0.059723824 | AR156: =I156/H156-1 -> -0.36669723 | AS156: =O156/N156-1 -> 0.07497813 | AT156: =Q156/P156-1 -> -0.12127927 | AU156: =S156/R156-1 -> -0.22628675 | AV156: =U156/T156-1 -> 0.36734258 | AW156: =W156/V156-1 -> -0.17399301 | AX156: =Y156/X156-1 -> -0.31822917 | AY156: =AA156/Z156-1 -> -0.54804047 | AZ156: =AK156/AJ156-1 -> -0.38159625 | BA156: =AC156/AB156-1 -> -0.078022209 | BB156: =AE156/AD156-1 -> -0.43406273 | BC156: =AM156/AL156-1 -> -0.17241646 | BD156: =IFERROR(AG156/AF156-1,1) -> 1 | BE156: =IFERROR(AI156/AH156-1,1) -> 1
A157: 45813 | B157: 38609736 | C157: 34179408 | D157: 3575822.2 | E157: 3527523 | F157: =SUM(N157,P157,R157,T157,V157) -> 2639487.2 | G157: =SUM(O157,Q157,S157,U157,W157) -> 2984995 | H157: =SUM(X157,Z157,AB157,AD157,AF157,AH157) -> 936335 | I157: =SUM(Y157,AA157,AC157,AE157,AG157,AI157) -> 542528 | J157: 46177 | K157: 6101558.8 | L157: 4601314 | M157: 1500244.7 | N157: 2405203 | O157: 2797805 | P157: 24530.172 | Q157: 20815 | R157: 28287 | S157: 73509 | T157: 7601 | U157: 4322 | V157: 173866 | W157: 88544 | X157: 649458 | Y157: 330252 | Z157: 251407 | AA157: 176072 | AB157: 22490 | AC157: 20525 | AD157: 12980 | AE157: 5500 | AF157: 0 | AG157: 5098 | AH157: 0 | AI157: 5081 | AJ157: =X157+Z157 -> 900865 | AK157: =Y157+AA157 -> 506324 | AL157: =AD157+AB157 -> 35470 | AM157: =AE157+AC157 -> 26025 | AN157: 46177 | AO157: =C157/B157-1 -> -0.11474639 | AP157: =E157/D157-1 -> -0.013507152 | AQ157: =G157/F157-1 -> 0.1308996 | AR157: =I157/H157-1 -> -0.42058345 | AS157: =O157/N157-1 -> 0.1632303 | AT157: =Q157/P157-1 -> -0.15145317 | AU157: =S157/R157-1 -> 1.5986849 | AV157: =U157/T157-1 -> -0.43139061 | AW157: =W157/V157-1 -> -0.49073424 | AX157: =Y157/X157-1 -> -0.49149599 | AY157: =AA157/Z157-1 -> -0.29965355 | AZ157: =AK157/AJ157-1 -> -0.43795796 | BA157: =AC157/AB157-1 -> -0.087372165 | BB157: =AE157/AD157-1 -> -0.57627119 | BC157: =AM157/AL157-1 -> -0.26628136 | BD157: =IFERROR(AG157/AF157-1,1) -> 1 | BE157: =IFERROR(AI157/AH157-1,1) -> 1
A158: 45814 | B158: 40369746 | C158: 36164915 | D158: 3043546.5 | E158: 2971920 | F158: =SUM(N158,P158,R158,T158,V158) -> 2233464.5 | G158: =SUM(O158,Q158,S158,U158,W158) -> 2416309 | H158: =SUM(X158,Z158,AB158,AD158,AF158,AH158) -> 810082 | I158: =SUM(Y158,AA158,AC158,AE158,AG158,AI158) -> 555611 | J158: 46178 | K158: 4663412.6 | L158: 3436840.6 | M158: 1226572.1 | N158: 2001508 | O158: 2265727 | P158: 24459.483 | Q158: 32888 | R158: 72867 | S158: 13246 | T158: 5878 | U158: 5193 | V158: 128752 | W158: 99255 | X158: 599700 | Y158: 351624 | Z158: 181701 | AA158: 180239 | AB158: 19333 | AC158: 11727 | AD158: 9348 | AE158: 6281 | AF158: 0 | AG158: 4449 | AH158: 0 | AI158: 1291 | AJ158: =X158+Z158 -> 781401 | AK158: =Y158+AA158 -> 531863 | AL158: =AD158+AB158 -> 28681 | AM158: =AE158+AC158 -> 18008 | AN158: 46178 | AO158: =C158/B158-1 -> -0.10415798 | AP158: =E158/D158-1 -> -0.023533888 | AQ158: =G158/F158-1 -> 0.081865872 | AR158: =I158/H158-1 -> -0.31412993 | AS158: =O158/N158-1 -> 0.13200996 | AT158: =Q158/P158-1 -> 0.34459098 | AU158: =S158/R158-1 -> -0.81821675 | AV158: =U158/T158-1 -> -0.11653624 | AW158: =W158/V158-1 -> -0.22909935 | AX158: =Y158/X158-1 -> -0.41366683 | AY158: =AA158/Z158-1 -> -0.0080461858 | AZ158: =AK158/AJ158-1 -> -0.31934692 | BA158: =AC158/AB158-1 -> -0.39342058 | BB158: =AE158/AD158-1 -> -0.32809157 | BC158: =AM158/AL158-1 -> -0.37212789 | BD158: =IFERROR(AG158/AF158-1,1) -> 1 | BE158: =IFERROR(AI158/AH158-1,1) -> 1
A159: 45815 | B159: 50222961 | C159: 47697211 | D159: 2666977.9 | E159: 2870666 | F159: =SUM(N159,P159,R159,T159,V159) -> 2030111.9 | G159: =SUM(O159,Q159,S159,U159,W159) -> 2315852 | H159: =SUM(X159,Z159,AB159,AD159,AF159,AH159) -> 636866 | I159: =SUM(Y159,AA159,AC159,AE159,AG159,AI159) -> 554814 | J159: 46179 | K159: 3963610.1 | L159: 2902425.8 | M159: 1061184.3 | N159: 1812078 | O159: 2159116 | P159: 25031.897 | Q159: 34578 | R159: 25976 | S159: 22387 | T159: 10248 | U159: 1996 | V159: 156778 | W159: 97775 | X159: 495806 | Y159: 344708 | Z159: 116017 | AA159: 188671 | AB159: 17934 | AC159: 9093 | AD159: 7109 | AE159: 3824 | AF159: 0 | AG159: 5418 | AH159: 0 | AI159: 3100 | AJ159: =X159+Z159 -> 611823 | AK159: =Y159+AA159 -> 533379 | AL159: =AD159+AB159 -> 25043 | AM159: =AE159+AC159 -> 12917 | AN159: 46179 | AO159: =C159/B159-1 -> -0.050290743 | AP159: =E159/D159-1 -> 0.076374125 | AQ159: =G159/F159-1 -> 0.14075091 | AR159: =I159/H159-1 -> -0.12883715 | AS159: =O159/N159-1 -> 0.19151383 | AT159: =Q159/P159-1 -> 0.38135758 | AU159: =S159/R159-1 -> -0.138166 | AV159: =U159/T159-1 -> -0.80523029 | AW159: =W159/V159-1 -> -0.37634745 | AX159: =Y159/X159-1 -> -0.30475226 | AY159: =AA159/Z159-1 -> 0.62623581 | AZ159: =AK159/AJ159-1 -> -0.12821355 | BA159: =AC159/AB159-1 -> -0.49297424 | BB159: =AE159/AD159-1 -> -0.46209031 | BC159: =AM159/AL159-1 -> -0.48420716 | BD159: =IFERROR(AG159/AF159-1,1) -> 1 | BE159: =IFERROR(AI159/AH159-1,1) -> 1
A160: 45816 | B160: 49920221 | C160: 50902735 | D160: 3220669.8 | E160: 3708782 | F160: =SUM(N160,P160,R160,T160,V160) -> 2412328.8 | G160: =SUM(O160,Q160,S160,U160,W160) -> 2956420 | H160: =SUM(X160,Z160,AB160,AD160,AF160,AH160) -> 808341 | I160: =SUM(Y160,AA160,AC160,AE160,AG160,AI160) -> 752362 | J160: 46180 | K160: 3472422.4 | L160: 2638146.2 | M160: 834276.25 | N160: 2272542 | O160: 2835754 | P160: 25757.759 | Q160: 33462 | R160: 21715 | S160: 1717 | T160: 6780 | U160: 3121 | V160: 85534 | W160: 82366 | X160: 642846 | Y160: 526670 | Z160: 139716 | AA160: 201401 | AB160: 16575 | AC160: 12585 | AD160: 9204 | AE160: 6574 | AF160: 0 | AG160: 2075 | AH160: 0 | AI160: 3057 | AJ160: =X160+Z160 -> 782562 | AK160: =Y160+AA160 -> 728071 | AL160: =AD160+AB160 -> 25779 | AM160: =AE160+AC160 -> 19159 | AN160: 46180 | AO160: =C160/B160-1 -> 0.019681684 | AP160: =E160/D160-1 -> 0.15155613 | AQ160: =G160/F160-1 -> 0.22554606 | AR160: =I160/H160-1 -> -0.069251714 | AS160: =O160/N160-1 -> 0.24783348 | AT160: =Q160/P160-1 -> 0.29910372 | AU160: =S160/R160-1 -> -0.92093023 | AV160: =U160/T160-1 -> -0.53967552 | AW160: =W160/V160-1 -> -0.037037903 | AX160: =Y160/X160-1 -> -0.18072135 | AY160: =AA160/Z160-1 -> 0.44150276 | AZ160: =AK160/AJ160-1 -> -0.069631544 | BA160: =AC160/AB160-1 -> -0.24072398 | BB160: =AE160/AD160-1 -> -0.28574533 | BC160: =AM160/AL160-1 -> -0.25679817 | BD160: =IFERROR(AG160/AF160-1,1) -> 1 | BE160: =IFERROR(AI160/AH160-1,1) -> 1
A161: 45817 | B161: 28800528 | C161: 28697109 | D161: 4519881.8 | E161: 5173290 | F161: =SUM(N161,P161,R161,T161,V161) -> 3580144.8 | G161: =SUM(O161,Q161,S161,U161,W161) -> 4242387 | H161: =SUM(X161,Z161,AB161,AD161,AF161,AH161) -> 939737 | I161: =SUM(Y161,AA161,AC161,AE161,AG161,AI161) -> 930903 | J161: 46181 | K161: 4193019.5 | L161: 3134115.9 | M161: 1058903.6 | N161: 3416740 | O161: 4038776 | P161: 24238.793 | Q161: 28413 | R161: 51991 | S161: 38880 | T161: 11309 | U161: 7184 | V161: 75866 | W161: 129134 | X161: 757315 | Y161: 693965 | Z161: 142907 | AA161: 192882 | AB161: 32343 | AC161: 27190 | AD161: 7172 | AE161: 4960 | AF161: 0 | AG161: 8849 | AH161: 0 | AI161: 3057 | AJ161: =X161+Z161 -> 900222 | AK161: =Y161+AA161 -> 886847 | AL161: =AD161+AB161 -> 39515 | AM161: =AE161+AC161 -> 32150 | AN161: 46181 | AO161: =C161/B161-1 -> -0.0035908717 | AP161: =E161/D161-1 -> 0.14456312 | AQ161: =G161/F161-1 -> 0.18497638 | AR161: =I161/H161-1 -> -0.0094005025 | AS161: =O161/N161-1 -> 0.18205541 | AT161: =Q161/P161-1 -> 0.17221183 | AU161: =S161/R161-1 -> -0.25217826 | AV161: =U161/T161-1 -> -0.36475374 | AW161: =W161/V161-1 -> 0.70213271 | AX161: =Y161/X161-1 -> -0.083650793 | AY161: =AA161/Z161-1 -> 0.34970295 | AZ161: =AK161/AJ161-1 -> -0.014857446 | BA161: =AC161/AB161-1 -> -0.1593235 | BB161: =AE161/AD161-1 -> -0.30842164 | BC161: =AM161/AL161-1 -> -0.18638492 | BD161: =IFERROR(AG161/AF161-1,1) -> 1 | BE161: =IFERROR(AI161/AH161-1,1) -> 1
A162: 45818 | B162: 33842549 | C162: 32882240 | D162: 4898086.7 | E162: 5209165 | F162: =SUM(N162,P162,R162,T162,V162) -> 3872939.7 | G162: =SUM(O162,Q162,S162,U162,W162) -> 4519578 | H162: =SUM(X162,Z162,AB162,AD162,AF162,AH162) -> 1025147 | I162: =SUM(Y162,AA162,AC162,AE162,AG162,AI162) -> 689587 | J162: 46182 | K162: 5905700.6 | L162: 4674672 | M162: 1231028.6 | N162: 3683319 | O162: 4305103 | P162: 22251.724 | Q162: 32400 | R162: 65685 | S162: 65678 | T162: 13660 | U162: 1844 | V162: 88024 | W162: 114553 | X162: 829750 | Y162: 480602 | Z162: 153054 | AA162: 174897 | AB162: 32493 | AC162: 13800 | AD162: 9850 | AE162: 7381 | AF162: 0 | AG162: 11271 | AH162: 0 | AI162: 1636 | AJ162: =X162+Z162 -> 982804 | AK162: =Y162+AA162 -> 655499 | AL162: =AD162+AB162 -> 42343 | AM162: =AE162+AC162 -> 21181 | AN162: 46182 | AO162: =C162/B162-1 -> -0.028375788 | AP162: =E162/D162-1 -> 0.063510161 | AQ162: =G162/F162-1 -> 0.16696317 | AR162: =I162/H162-1 -> -0.32732867 | AS162: =O162/N162-1 -> 0.16881079 | AT162: =Q162/P162-1 -> 0.45606695 | AU162: =S162/R162-1 -> -0.00010656923 | AV162: =U162/T162-1 -> -0.86500732 | AW162: =W162/V162-1 -> 0.30138371 | AX162: =Y162/X162-1 -> -0.42078698 | AY162: =AA162/Z162-1 -> 0.14271434 | AZ162: =AK162/AJ162-1 -> -0.33303182 | BA162: =AC162/AB162-1 -> -0.57529314 | BB162: =AE162/AD162-1 -> -0.2506599 | BC162: =AM162/AL162-1 -> -0.49977564 | BD162: =IFERROR(AG162/AF162-1,1) -> 1 | BE162: =IFERROR(AI162/AH162-1,1) -> 1
A163: 45819 | B163: 38225481 | C163: 37140797 | D163: 4461529 | E163: 4905225 | F163: =SUM(N163,P163,R163,T163,V163) -> 3335643 | G163: =SUM(O163,Q163,S163,U163,W163) -> 4319205 | H163: =SUM(X163,Z163,AB163,AD163,AF163,AH163) -> 1125886 | I163: =SUM(Y163,AA163,AC163,AE163,AG163,AI163) -> 586020 | J163: 46183 | K163: 6407621.7 | L163: 5064708.5 | M163: 1342913.3 | N163: 3146636 | O163: 4123039 | P163: 19800 | Q163: 28567 | R163: 47481 | S163: 28987 | T163: 1700 | U163: 6055 | V163: 120026 | W163: 132557 | X163: 948224 | Y163: 415988 | Z163: 139153 | AA163: 141262 | AB163: 23874 | AC163: 21700 | AD163: 14635 | AE163: 2811 | AF163: 0 | AG163: 4259 | AH163: 0 | AI163: 0 | AJ163: =X163+Z163 -> 1087377 | AK163: =Y163+AA163 -> 557250 | AL163: =AD163+AB163 -> 38509 | AM163: =AE163+AC163 -> 24511 | AN163: 46183 | AO163: =C163/B163-1 -> -0.028375941 | AP163: =E163/D163-1 -> 0.099449314 | AQ163: =G163/F163-1 -> 0.29486429 | AR163: =I163/H163-1 -> -0.47950325 | AS163: =O163/N163-1 -> 0.31030059 | AT163: =Q163/P163-1 -> 0.44277778 | AU163: =S163/R163-1 -> -0.38950317 | AV163: =U163/T163-1 -> 2.5617647 | AW163: =W163/V163-1 -> 0.10440238 | AX163: =Y163/X163-1 -> -0.56129775 | AY163: =AA163/Z163-1 -> 0.015155979 | AZ163: =AK163/AJ163-1 -> -0.48752824 | BA163: =AC163/AB163-1 -> -0.091061406 | BB163: =AE163/AD163-1 -> -0.8079262 | BC163: =AM163/AL163-1 -> -0.36349944 | BD163: =IFERROR(AG163/AF163-1,1) -> 1 | BE163: =IFERROR(AI163/AH163-1,1) -> 1
A164: 45820 | B164: 44572329 | C164: 35683971 | D164: 3866377.4 | E164: 3824147 | F164: =SUM(N164,P164,R164,T164,V164) -> 2753484.4 | G164: =SUM(O164,Q164,S164,U164,W164) -> 3178208 | H164: =SUM(X164,Z164,AB164,AD164,AF164,AH164) -> 1112893 | I164: =SUM(Y164,AA164,AC164,AE164,AG164,AI164) -> 645939 | J164: 46184 | K164: 5835819.3 | L164: 4360940.9 | M164: 1474878.5 | N164: 2555955 | O164: 2993082 | P164: 25116.379 | Q164: 24347 | R164: 47507 | S164: 18478 | T164: 12578 | U164: 2267 | V164: 112328 | W164: 140034 | X164: 947866 | Y164: 412479 | Z164: 131048 | AA164: 215146 | AB164: 20426 | AC164: 12955 | AD164: 13553 | AE164: 214 | AF164: 0 | AG164: 4069 | AH164: 0 | AI164: 1076 | AJ164: =X164+Z164 -> 1078914 | AK164: =Y164+AA164 -> 627625 | AL164: =AD164+AB164 -> 33979 | AM164: =AE164+AC164 -> 13169 | AN164: 46184 | AO164: =C164/B164-1 -> -0.19941426 | AP164: =E164/D164-1 -> -0.010922467 | AQ164: =G164/F164-1 -> 0.15424951 | AR164: =I164/H164-1 -> -0.41958571 | AS164: =O164/N164-1 -> 0.17102296 | AT164: =Q164/P164-1 -> -0.030632573 | AU164: =S164/R164-1 -> -0.61104679 | AV164: =U164/T164-1 -> -0.81976467 | AW164: =W164/V164-1 -> 0.24665266 | AX164: =Y164/X164-1 -> -0.56483406 | AY164: =AA164/Z164-1 -> 0.64173433 | AZ164: =AK164/AJ164-1 -> -0.41828079 | BA164: =AC164/AB164-1 -> -0.36575933 | BB164: =AE164/AD164-1 -> -0.98421014 | BC164: =AM164/AL164-1 -> -0.61243709 | BD164: =IFERROR(AG164/AF164-1,1) -> 1 | BE164: =IFERROR(AI164/AH164-1,1) -> 1
A165: 45821 | B165: 48087656 | C165: 38806927 | D165: 2794859.4 | E165: 3614931 | F165: =SUM(N165,P165,R165,T165,V165) -> 1862655.4 | G165: =SUM(O165,Q165,S165,U165,W165) -> 2794758 | H165: =SUM(X165,Z165,AB165,AD165,AF165,AH165) -> 932204 | I165: =SUM(Y165,AA165,AC165,AE165,AG165,AI165) -> 820173 | J165: 46185 | K165: 5045229.5 | L165: 3587371.5 | M165: 1457858 | N165: 1667347 | O165: 2651227 | P165: 28341.379 | Q165: 30709 | R165: 42888 | S165: 11629 | T165: 9320 | U165: 3889 | V165: 114759 | W165: 97304 | X165: 766146 | Y165: 566709 | Z165: 144596 | AA165: 221811 | AB165: 10631 | AC165: 20101 | AD165: 10831 | AE165: 2802 | AF165: 0 | AG165: 6123 | AH165: 0 | AI165: 2627 | AJ165: =X165+Z165 -> 910742 | AK165: =Y165+AA165 -> 788520 | AL165: =AD165+AB165 -> 21462 | AM165: =AE165+AC165 -> 22903 | AN165: 46185 | AO165: =C165/B165-1 -> -0.19299608 | AP165: =E165/D165-1 -> 0.29342142 | AQ165: =G165/F165-1 -> 0.50041604 | AR165: =I165/H165-1 -> -0.12017863 | AS165: =O165/N165-1 -> 0.59008713 | AT165: =Q165/P165-1 -> 0.08353936 | AU165: =S165/R165-1 -> -0.72885189 | AV165: =U165/T165-1 -> -0.58272532 | AW165: =W165/V165-1 -> -0.15210136 | AX165: =Y165/X165-1 -> -0.260312 | AY165: =AA165/Z165-1 -> 0.53400509 | AZ165: =AK165/AJ165-1 -> -0.13420047 | BA165: =AC165/AB165-1 -> 0.89079108 | BB165: =AE165/AD165-1 -> -0.74129813 | BC165: =AM165/AL165-1 -> 0.067141925 | BD165: =IFERROR(AG165/AF165-1,1) -> 1 | BE165: =IFERROR(AI165/AH165-1,1) -> 1
... A245: 45901 | B245: 31649055 | C245: 0 | D245: 4990529.1 | E245: 0 | F245: =SUM(N245,P245,R245,T245,V245) -> 4080895.9 | G245: =SUM(O245,Q245,S245,U245,W245) -> 0 | H245: =SUM(X245,Z245,AB245,AD245,AF245,AH245) -> 909633.16 | I245: =SUM(Y245,AA245,AC245,AE245,AG245,AI245) -> 0 | J245: 46265 | K245: 5496657.2 | L245: 3961469.1 | M245: 1535188.1 | N245: 3909270 | O245: 0 | P245: 26356.897 | Q245: 0 | R245: 17828 | S245: 0 | T245: 10082 | U245: 0 | V245: 117359 | W245: 0 | X245: 480576 | Y245: 0 | Z245: 371920 | AA245: 0 | AB245: 38723 | AC245: 0 | AD245: 18027 | AE245: 0 | AF245: 387.15517 | AG245: 0 | AH245: 0 | AI245: 0 | AJ245: =X245+Z245 -> 852496 | AK245: =Y245+AA245 -> 0 | AL245: =AD245+AB245 -> 56750 | AM245: =AE245+AC245 -> 0 | AN245: 46265 | AO245: =C245/B245-1 -> -1 | AP245: =E245/D245-1 -> -1 | AQ245: =G245/F245-1 -> -1 | AR245: =I245/H245-1 -> -1 | AS245: =O245/N245-1 -> -1 | AT245: =Q245/P245-1 -> -1 | AU245: =S245/R245-1 -> -1 | AV245: =U245/T245-1 -> -1 | AW245: =W245/V245-1 -> -1 | AX245: =Y245/X245-1 -> -1 | AY245: =AA245/Z245-1 -> -1 | AZ245: =AK245/AJ245-1 -> -1 | BA245: =AC245/AB245-1 -> -1 | BB245: =AE245/AD245-1 -> -1 | BC245: =AM245/AL245-1 -> -1 | BD245: =IFERROR(AG245/AF245-1,1) -> -1 | BE245: =IFERROR(AI245/AH245-1,1) -> 1

Sheet afil
A3: Etiquetas de fila | B3: Suma de Afiliados 2025 | E3: Etiquetas de columna
A4: ene | B4: 735903.45 | E4: ene | F4: feb | G4: mar | H4: abr | I4: may | J4: jun | K4: jul | L4: ago | M4: sep | N4: Total general
A5: feb | B5: 577281.03 | D5: Suma de Afiliados 2026 | E5: 828398 | F5: 690246 | G5: 781473 | H5: 655793 | I5: 733475 | J5: 933595 | K5: 1134357 | L5: 1006487 | M5: 0 | N5: 6763824
A6: mar | B6: 628597.41
A7: abr | B7: 537415.52
A8: may | B8: 690044.83
A9: jun | B9: 1043100.9
A10: jul | B10: 1288231.9
A11: ago | B11: 1233300
A12: sep | B12: 26356.897
A13: Total general | B13: 6760231.9

Sheet 2025
A3: Etiquetas de fila | B3: Suma de Web + APP 2025 | C3: Suma de TMK 2025 | D3: Suma de WA 2025 | E3: Suma de Ent. en Tienda 2025 | F3: Suma de Meli Drop 2025 | G3: Suma de Meli Full 2025 | H3: Suma de Amazon Drop 2025 | I3: Suma de Amazon Full 2025 | J3: Suma de TikTok 2025 | K3: Suma de Shein 2025 | L3: Suma de Global 2025
A4: ene | B4: 64774122 | C4: 1448010 | D4: 110309 | E4: 1740843 | F4: 12634416 | G4: 2796767 | H4: 1549978 | I4: 337627 | J4: 0 | K4: 0 | L4: 988946355
A5: feb | B5: 62779662 | C5: 1441236 | D5: 110248 | E5: 1727351 | F5: 8028750 | G5: 1592434 | H5: 784689 | I5: 145354 | J5: 0 | K5: 0 | L5: 962218940
A6: mar | B6: 70846957 | C6: 1430022 | D6: 105504 | E6: 1895057 | F6: 12534250 | G6: 3477562 | H6: 516151 | I6: 262286 | J6: 0 | K6: 0 | L6: 1186617098
A7: abr | B7: 64872371 | C7: 1319157 | D7: 228719 | E7: 1991672 | F7: 10402707 | G7: 2880496 | H7: 565896 | I7: 256773 | J7: 0 | K7: 0 | L7: 1035672463
A8: may | B8: 77993633 | C8: 1186894 | D8: 193949 | E8: 2807631 | F8: 17783854 | G8: 4277531 | H8: 740101 | I8: 340898 | J8: 0 | K8: 0 | L8: 1152795410
A9: jun | B9: 81146441 | C9: 1075608 | D9: 224382 | E9: 3214064 | F9: 21666219 | G9: 4885568 | H9: 1068283 | I9: 357640 | J9: 0 | K9: 0 | L9: 1224352130
A10: jul | B10: 85926647 | C10: 993236 | D10: 183021 | E10: 3267791 | F10: 18674810 | G10: 3524088 | H10: 1034594 | I10: 335023 | J10: 0 | K10: 0 | L10: 1257444654
A11: ago | B11: 108478992 | C11: 1181596 | D11: 171602 | E11: 4704001 | F11: 21315555 | G11: 6687463 | H11: 1121624 | I11: 277354 | J11: 14518.138 | K11: 1292.2414 | L11: 1609737016
A12: sep | B12: 87878561 | C12: 968361 | D12: 119486 | E12: 2988851 | F12: 15767135 | G12: 5457540 | H12: 948229 | I12: 215658 | J12: 38105.845 | K12: 5684.4828 | L12: 1126051534
A13: oct | B13: 103771731 | C13: 1262970 | D13: 103398 | E13: 4707733 | F13: 17529528 | G13: 4813818 | H13: 1206578 | I13: 274614 | J13: 159945.12 | K13: 17652.586 | L13: 1287742925
A14: nov | B14: 121922567 | C14: 1422628 | D14: 115811 | E14: 4688825 | F14: 28802133 | G14: 7493286 | H14: 1364853 | I14: 832825 | J14: 236535.45 | K14: 38752.586 | L14: 1645378487
A15: dic | B15: 121938684 | C15: 1363878 | D15: 108517 | E15: 4638343 | F15: 43762583 | G15: 8916467 | H15: 2302519 | I15: 3036049 | J15: 350116.9 | K15: 8956.0345 | L15: 2226063308
A16: Total general | B16: 1052330368 | C16: 15093596 | D16: 1774946 | E16: 38372162 | F16: 228901940 | G16: 56803020 | H16: 13203495 | I16: 6672101 | J16: 799221.45 | K16: 72337.931 | L16: 15703020320
A19: Etiquetas de fila | B19: Suma de Meli Full 2025 | C19: Suma de Meli Drop 2025 | D19: Suma de Meli Drop 2026 | E19: Suma de Meli Full 2026 | G19: MELI 2025 | H19: MELI 2026 | I19: %VAR
A20: ene | B20: 2796767 | C20: 12634416 | D20: 15141562 | E20: 3117450 | F20: ene | G20: =SUM(B20:C20) -> 15431183 | H20: =SUM(D20:E20) -> 18259012 | I20: =H20/G20-1 -> 0.18325419
A21: feb | B21: 1592434 | C21: 8028750 | D21: 11257443 | E21: 1820069 | F21: feb | G21: =SUM(B21:C21) -> 9621184 | H21: =SUM(D21:E21) -> 13077512 | I21: =H21/G21-1 -> 0.35924144
A22: mar | B22: 3477562 | C22: 12534250 | D22: 14502060 | E22: 2278267 | F22: mar | G22: =SUM(B22:C22) -> 16011812 | H22: =SUM(D22:E22) -> 16780327 | I22: =H22/G22-1 -> 0.047996754
A23: abr | B23: 2880496 | C23: 10402707 | D23: 10291831 | E23: 2417828 | F23: abr | G23: =SUM(B23:C23) -> 13283203 | H23: =SUM(D23:E23) -> 12709659 | I23: =H23/G23-1 -> -0.04317814
A24: may | B24: 4277531 | C24: 17783854 | D24: 15146494 | E24: 4400759 | F24: may | G24: =SUM(B24:C24) -> 22061385 | H24: =SUM(D24:E24) -> 19547253 | I24: =H24/G24-1 -> -0.11396075
A25: jun | B25: 4885568 | C25: 21666219 | D25: 16071142 | E25: 5207754 | F25: jun | G25: =SUM(B25:C25) -> 26551787 | H25: =SUM(D25:E25) -> 21278896 | I25: =H25/G25-1 -> -0.19858893 | J25: =E25/B25-1 -> 0.065946477 | K25: =E25/B25-1 -> 0.065946477
A26: jul | B26: 3524088 | C26: 18674810 | D26: 9647154 | E26: 3148801 | F26: jul | G26: =SUM(B26:C26) -> 22198898 | H26: =SUM(D26:E26) -> 12795955 | I26: =H26/G26-1 -> -0.42357702 | J26: =E26/B26-1 -> -0.10649195 | K26: =E26/B26-1 -> -0.10649195
A27: ago | B27: 6687463 | C27: 21315555 | D27: 14363472 | E27: 5950435 | F27: ago | G27: =SUM(B27:C27) -> 28003018 | H27: =SUM(D27:E27) -> 20313907 | I27: =H27/G27-1 -> -0.27458151 | J27: =E27/B27-1 -> -0.1102104 | K27: =E27/B27-1 -> -0.1102104
A28: sep | B28: 5457540 | C28: 15767135 | F28: sep | G28: =SUM(B28:C28) -> 21224675 | H28: =SUM(D28:E28) -> 0
A29: oct | B29: 4813818 | C29: 17529528 | F29: oct | G29: =SUM(B29:C29) -> 22343346 | H29: =SUM(D29:E29) -> 0
A30: nov | B30: 7493286 | C30: 28802133 | F30: nov | G30: =SUM(B30:C30) -> 36295419 | H30: =SUM(D30:E30) -> 0
A31: dic | B31: 8916467 | C31: 43762583 | F31: dic | G31: =SUM(B31:C31) -> 52679050 | H31: =SUM(D31:E31) -> 0
A32: Total general | B32: 56803020 | C32: 228901940 | D32: 106421158 | E32: 28341363 | G32: =SUM(G20:G27) -> 153162470 | H32: =SUM(H20:H31) -> 134762521 | I32: =H32/G32-1 -> -0.12013354

Sheet may-ago
A3: Meses (2026) | B3: Días (2026) | C3: Web + APP 2026 | D3: Afiliados 2026 | E3: TMK 2026 | F3: WA 2026 | G3: Ent. en Tienda 2026 | H3: Meli Drop 2026 | I3: Meli Full 2026 | J3: Amazon Drop 2026 | K3: Amazon Full 2026 | L3: TikTok 2026 | M3: Shein 2026 | N3: Venta Total 2026 | O3: DIGITAL TOTAL | P3: MKP TOTAL
A4: may | B4: 01-may | C4: 2069924 | D4: 31463 | E4: 2522 | F4: 0 | G4: 33966 | H4: 215596 | I4: 89389 | J4: 23623 | K4: 9448 | L4: 2225 | M4: 3134 | N4: 2481290 | O4: =SUM(C4:G4) -> 2137875 | P4: =SUM(H4:M4) -> 343415
B5: 02-may | C5: 1930522 | D5: 20804 | E5: -732 | F5: 1144 | G5: 87762 | H5: 178276 | I5: 69883 | J5: 10926 | K5: 4862 | L5: 447 | M5: 4607 | N5: 2308501 | O5: =SUM(C5:G5) -> 2039500 | P5: =SUM(H5:M5) -> 269001
B6: 03-may | C6: 2628259 | D6: 23026 | E6: 11669 | F6: 740 | G6: 66322 | H6: 227157 | I6: 91628 | J6: 19133 | K6: 8602 | L6: 370 | M6: 5416 | N6: 3082322 | O6: =SUM(C6:G6) -> 2730016 | P6: =SUM(H6:M6) -> 352306
B7: 04-may | C7: 4124173 | D7: 25420 | E7: 28207 | F7: 5623 | G7: 67376 | H7: 521359 | I7: 170941 | J7: 18893 | K7: 10593 | L7: 2031 | M7: 2109 | N7: 4976725 | O7: =SUM(C7:G7) -> 4250799 | P7: =SUM(H7:M7) -> 725926
B8: 05-may | C8: 4494478 | D8: 24526 | E8: 55447 | F8: 6329 | G8: 70316 | H8: 610542 | I8: 206091 | J8: 34471 | K8: 15053 | L8: 4388 | M8: 4047 | N8: 5525688 | O8: =SUM(C8:G8) -> 4651096 | P8: =SUM(H8:M8) -> 874592
B9: 06-may | C9: 4088680 | D9: 22236 | E9: 15858 | F9: 0 | G9: 103050 | H9: 584166 | I9: 168986 | J9: 21276 | K9: 9621 | L9: 4594 | M9: 0 | N9: 5018467 | O9: =SUM(C9:G9) -> 4229824 | P9: =SUM(H9:M9) -> 788643
B10: 07-may | C10: 3214171 | D10: 22409 | E10: 45962 | F10: 0 | G10: 87902 | H10: 433044 | I10: 142471 | J10: 10390 | K10: 7381 | L10: 2879 | M10: 1248 | N10: 3967857 | O10: =SUM(C10:G10) -> 3370444 | P10: =SUM(H10:M10) -> 597413
B11: 08-may | C11: 1615018 | D11: 19192 | E11: 7092 | F11: 1998 | G11: 52205 | H11: 453556 | I11: 262519 | J11: 32442 | K11: 12700 | L11: 3174 | M11: 1464 | N11: 2461360 | O11: =SUM(C11:G11) -> 1695505 | P11: =SUM(H11:M11) -> 765855
B12: 09-may | C12: 1558074 | D12: 23729 | E12: 12190 | F12: 4102 | G12: 87416 | H12: 361074 | I12: 192329 | J12: 9552 | K12: 10260 | L12: 388 | M12: 646 | N12: 2259760 | O12: =SUM(C12:G12) -> 1685511 | P12: =SUM(H12:M12) -> 574249
B13: 10-may | C13: 1920563 | D13: 20514 | E13: -705 | F13: 2209 | G13: 48263 | H13: 395528 | I13: 141929 | J13: 24844 | K13: 7362 | L13: 256 | M13: 0 | N13: 2560763 | O13: =SUM(C13:G13) -> 1990844 | P13: =SUM(H13:M13) -> 569919
B14: 11-may | C14: 2440025 | D14: 21672 | E14: 29073 | F14: 5953 | G14: 60459 | H14: 409424 | I14: 123764 | J14: 11328 | K14: 10655 | L14: 991 | M14: 2109 | N14: 3115453 | O14: =SUM(C14:G14) -> 2557182 | P14: =SUM(H14:M14) -> 558271
B15: 12-may | C15: 2815317 | D15: 21451 | E15: 23262 | F15: 3933 | G15: 54841 | H15: 383123 | I15: 135469 | J15: 16632 | K15: 10371 | L15: 1022 | M15: 4650 | N15: 3470071 | O15: =SUM(C15:G15) -> 2918804 | P15: =SUM(H15:M15) -> 551267
B16: 13-may | C16: 3700459 | D16: 26216 | E16: 28501 | F16: 4829 | G16: 57302 | H16: 381201 | I16: 138856 | J16: 19491 | K16: 6421 | L16: 1247 | M16: 1937 | N16: 4366460 | O16: =SUM(C16:G16) -> 3817307 | P16: =SUM(H16:M16) -> 549153
... B34: 31-may | C34: 2739282 | D34: 36548 | E34: 7405 | F34: 4382 | G34: 80380 | H34: 1043225 | I34: 173161 | J34: 23659 | K34: 10923 | L34: 2086 | M34: 5728 | N34: 4126779 | O34: =SUM(C34:G34) -> 2867997 | P34: =SUM(H34:M34) -> 1258782
A35: Total may | C35: 94288932 | D35: 756439 | E35: 632168 | F35: 86712 | G35: 2472615 | H35: 15146494 | I35: 4400759 | J35: 643572 | K35: 286055 | L35: 78948 | M35: 105171 | N35: 118897865 | O35: =SUM(C35:G35) -> 98236866 | P35: =SUM(H35:M35) -> 20660999
A36: jun | B36: 01-jun | C36: 4064668 | D36: 29432 | E36: 26689 | F36: 10478 | G36: 92432 | H36: 904974 | I36: 135586 | J36: 29579 | K36: 10801 | L36: 8208 | M36: 8913 | N36: 5321760 | O36: =SUM(C36:G36) -> 4223699 | P36: =SUM(H36:M36) -> 1098061
B37: 02-jun | C37: 4572359 | D37: 23766 | E37: 47963 | F37: 15476 | G37: 108290 | H37: 930339 | I37: 178091 | J37: 32506 | K37: 12255 | L37: 4331 | M37: 4564 | N37: 5929940 | O37: =SUM(C37:G37) -> 4767854 | P37: =SUM(H37:M37) -> 1162086
B38: 03-jun | C38: 3552563 | D38: 26173 | E38: 32530 | F38: 6406 | G38: 121708 | H38: 539970 | I38: 136278 | J38: 35037 | K38: 7759 | L38: 4912 | M38: 1334 | N38: 4464670 | O38: =SUM(C38:G38) -> 3739380 | P38: =SUM(H38:M38) -> 725290
B39: 04-jun | C39: 2797805 | D39: 20815 | E39: 73509 | F39: 4322 | G39: 88544 | H39: 330252 | I39: 176072 | J39: 20525 | K39: 5500 | L39: 5098 | M39: 5081 | N39: 3527523 | O39: =SUM(C39:G39) -> 2984995 | P39: =SUM(H39:M39) -> 542528
B40: 05-jun | C40: 2265727 | D40: 32888 | E40: 13246 | F40: 5193 | G40: 99255 | H40: 351624 | I40: 180239 | J40: 11727 | K40: 6281 | L40: 4449 | M40: 1291 | N40: 2971920 | O40: =SUM(C40:G40) -> 2416309 | P40: =SUM(H40:M40) -> 555611
B41: 06-jun | C41: 2159116 | D41: 34578 | E41: 22387 | F41: 1996 | G41: 97775 | H41: 344708 | I41: 188671 | J41: 9093 | K41: 3824 | L41: 5418 | M41: 3100 | N41: 2870666 | O41: =SUM(C41:G41) -> 2315852 | P41: =SUM(H41:M41) -> 554814
B42: 07-jun | C42: 2835754 | D42: 33462 | E42: 1717 | F42: 3121 | G42: 82366 | H42: 526670 | I42: 201401 | J42: 12585 | K42: 6574 | L42: 2075 | M42: 3057 | N42: 3708782 | O42: =SUM(C42:G42) -> 2956420 | P42: =SUM(H42:M42) -> 752362
B43: 08-jun | C43: 4038776 | D43: 28413 | E43: 38880 | F43: 7184 | G43: 129134 | H43: 693965 | I43: 192882 | J43: 27190 | K43: 4960 | L43: 8849 | M43: 3057 | N43: 5173290 | O43: =SUM(C43:G43) -> 4242387 | P43: =SUM(H43:M43) -> 930903
B44: 09-jun | C44: 4305103 | D44: 32400 | E44: 65678 | F44: 1844 | G44: 114553 | H44: 480602 | I44: 174897 | J44: 13800 | K44: 7381 | L44: 11271 | M44: 1636 | N44: 5209165 | O44: =SUM(C44:G44) -> 4519578 | P44: =SUM(H44:M44) -> 689587
B45: 10-jun | C45: 4123039 | D45: 28567 | E45: 28987 | F45: 6055 | G45: 132557 | H45: 415988 | I45: 141262 | J45: 21700 | K45: 2811 | L45: 4259 | M45: 0 | N45: 4905225 | O45: =SUM(C45:G45) -> 4319205 | P45: =SUM(H45:M45) -> 586020
B46: 11-jun | C46: 2993082 | D46: 24347 | E46: 18478 | F46: 2267 | G46: 140034 | H46: 412479 | I46: 215146 | J46: 12955 | K46: 214 | L46: 4069 | M46: 1076 | N46: 3824147 | O46: =SUM(C46:G46) -> 3178208 | P46: =SUM(H46:M46) -> 645939
B47: 12-jun | C47: 2651227 | D47: 30709 | E47: 11629 | F47: 3889 | G47: 97304 | H47: 566709 | I47: 221811 | J47: 20101 | K47: 2802 | L47: 6123 | M47: 2627 | N47: 3614931 | O47: =SUM(C47:G47) -> 2794758 | P47: =SUM(H47:M47) -> 820173
B48: 13-jun | C48: 2172069 | D48: 41533 | E48: 29771 | F48: 2610 | G48: 43950 | H48: 427855 | I48: 215157 | J48: 16395 | K48: 3162 | L48: -34 | M48: 3272 | N48: 2955740 | O48: =SUM(C48:G48) -> 2289933 | P48: =SUM(H48:M48) -> 665807
... B65: 30-jun | C65: 4003008 | D65: 33147 | E65: 7770 | F65: 4521 | G65: 83644 | H65: 771777 | I65: 155445 | J65: 49773 | K65: 13299 | L65: 4538 | M65: 1937 | N65: 5128859 | O65: =SUM(C65:G65) -> 4132090 | P65: =SUM(H65:M65) -> 996769
A66: Total jun | C66: 97249818 | D66: 930194 | E66: 754232 | F66: 104106 | G66: 2740552 | H66: 16071142 | I66: 5207754 | J66: 749766 | K66: 243242 | L66: 196887 | M66: 90033 | N66: 124337726 | O66: =SUM(C66:G66) -> 101778902 | P66: =SUM(H66:M66) -> 22558824
A67: jul | B67: 01-jul | C67: 3854991 | D67: 33555 | E67: 37725 | F67: 3591 | G67: 72458 | H67: 625555 | I67: 147936 | J67: 54054 | K67: 17511 | L67: 6232 | M67: 1455 | N67: 4855063 | O67: =SUM(C67:G67) -> 4002320 | P67: =SUM(H67:M67) -> 852743
B68: 02-jul | C68: 2923874 | D68: 33721 | E68: 11767 | F68: 4184 | G68: 86120 | H68: 529374 | I68: 154761 | J68: 37080 | K68: 17915 | L68: 9869 | M68: 6287 | N68: 3814952 | O68: =SUM(C68:G68) -> 3059666 | P68: =SUM(H68:M68) -> 755286
B69: 03-jul | C69: 2705057 | D69: 43805 | E69: 17931 | F69: 1013 | G69: 84930 | H69: 337385 | I69: 118065 | J69: 42831 | K69: 10140 | L69: 10620 | M69: 1894 | N69: 3373671 | O69: =SUM(C69:G69) -> 2852736 | P69: =SUM(H69:M69) -> 520935
B70: 04-jul | C70: 2175054 | D70: 41461 | E70: 4234 | F70: 345 | G70: 73695 | H70: 476598 | I70: 108307 | J70: 37222 | K70: 7925 | L70: 56771 | M70: 2583 | N70: 2984195 | O70: =SUM(C70:G70) -> 2294789 | P70: =SUM(H70:M70) -> 689406
B71: 05-jul | C71: 2221020 | D71: 34456 | E71: -5691 | F71: 2342 | G71: 40115 | H71: 421919 | I71: 88467 | J71: 39269 | K71: 5114 | L71: 13798 | M71: 3488 | N71: 2864297 | O71: =SUM(C71:G71) -> 2292242 | P71: =SUM(H71:M71) -> 572055
B72: 06-jul | C72: 3592240 | D72: 37084 | E72: 13165 | F72: 3678 | G72: 43263 | H72: 516899 | I72: 122255 | J72: 22297 | K72: 3480 | L72: 17060 | M72: 3660 | N72: 4375081 | O72: =SUM(C72:G72) -> 3689430 | P72: =SUM(H72:M72) -> 685651
B73: 07-jul | C73: 3881350 | D73: 42546 | E73: 27712 | F73: 2534 | G73: 61051 | H73: 691715 | I73: 150430 | J73: 17456 | K73: 2549 | L73: 8033 | M73: 6201 | N73: 4891577 | O73: =SUM(C73:G73) -> 4015193 | P73: =SUM(H73:M73) -> 876384
B74: 08-jul | C74: 3404528 | D74: 36707 | E74: 48817 | F74: 4184 | G74: 89941 | H74: 628785 | I74: 147851 | J74: 25750 | K74: 5197 | L74: 8617 | M74: 1205 | N74: 4401582 | O74: =SUM(C74:G74) -> 3584177 | P74: =SUM(H74:M74) -> 817405
B75: 09-jul | C75: 3166533 | D75: 41275 | E75: 14603 | F75: 4141 | G75: 38529 | H75: 318377 | I75: 87484 | J75: 14199 | K75: 6363 | L75: 6495 | M75: 1248 | N75: 3699247 | O75: =SUM(C75:G75) -> 3265081 | P75: =SUM(H75:M75) -> 434166
...

Sheet BD MD
C1: =+SUM(C3:C389) -> 1.4288748e+09 | G1: =+H1-H2 -> -1.0326591e+08 | H1: =+K2+O2+Q2+S2 -> 856993833 | J1: =+SUM(J3:J389) -> 1054900164 | L1: =+SUM(L3:L389) -> 11651867 | N1: =+SUM(N3:N389) -> 15094810 | P1: =+SUM(P3:P389) -> 1776830 | R1: =+SUM(R3:R389) -> 38370811 | T1: =+SUM(T3:T389) -> 229449233 | V1: =+SUM(V3:V389) -> 56838215 | X1: =+SUM(X3:X389) -> 13236238 | Z1: =+SUM(Z3:Z389) -> 6683046 | AB1: =+SUM(AB3:AB389) -> 801237.45 | AD1: =+SUM(AD3:AD389) -> 72337.931 | AE1: =+AD1+AB1+Z1+X1+V1+T1 -> 3.0708031e+08 | AF1: =+AC2+AA2+Y2+W2+U2 -> 165066124 | AP1: =AP2+AQ2 -> 9.3086203e+08 | AR1: =AR2+AS2 -> 1031500327 | AT1: =+AR1/AP1-1 -> 0.10811301 | AV1: =+AW2+AV2 -> 1.204792e+09 | AW1: =+AR1/AV1-1 -> -0.14383533 | BC1: =BC2+BD2 -> -1.7329165e+08 | BE1: =BE2+BF2 -> 1.5537545e+08
B2: =+SUBTOTAL(9,B4:B274) -> 10512401494 | C2: =+SUBTOTAL(9,C4:C274) -> 9.3086203e+08 | E2: =+SUBTOTAL(9,E4:E274) -> 10345159441 | G2: =+SUBTOTAL(9,G4:G274) -> 1.204792e+09 | H2: =+SUBTOTAL(9,H4:H274) -> 9.6025975e+08 | I2: =+SUBTOTAL(9,I4:I274) -> 2.4453223e+08 | J2: =+SUBTOTAL(9,J4:J274) -> 702116637 | K2: =+SUBTOTAL(9,K4:K274) -> 826123931 | L2: =+SUBTOTAL(9,L4:L274) -> 7600937.9 | M2: =+SUBTOTAL(9,M4:M274) -> 8859591 | N2: =+SUBTOTAL(9,N4:N274) -> 11013015 | ... AF2: =+SUBTOTAL(9,AF4:AF274) -> 1031500327 | AG2: =+AF2/G2 -> 0.85616467 | AH2: =+SUBTOTAL(9,AH4:AH274) -> -1.7329165e+08 | AI2: =+AF2/C2-1 -> 0.10811301 | AJ2: =+C2/B2 -> 0.088548942 | AK2: =+AF2/E2 -> 0.0997085 | AL2: =+E2/B2-1 -> -0.015909025 | AP2: =+SUBTOTAL(9,AP4:AP274) -> 7.464155e+08 | AQ2: =+SUBTOTAL(9,AQ4:AQ274) -> 1.8444653e+08 | AR2: =+SUBTOTAL(9,AR4:AR274) -> 865853424 | AS2: =+SUBTOTAL(9,AS4:AS274) -> 165646903 | AV2: =+SUBTOTAL(9,AV4:AV274) -> 9.6025975e+08 | AW2: =+SUBTOTAL(9,AW4:AW274) -> 2.4453223e+08 | BC2: =+SUBTOTAL(9,BC4:BC274) -> -94406323 | BD2: =+SUBTOTAL(9,BD4:BD274) -> -78885326 | BE2: =+SUBTOTAL(9,BE4:BE274) -> 1.3636048e+08 | BF2: =+SUBTOTAL(9,BF4:BF274) -> 19014970
A3: 2025 | B3: Global 2025 | C3: Vta 2025 | D3: Share diario | E3: Global 2026 | F3: 2026 | G3: Venta Meta 2026 | H3: Meta Digital | I3: Meta MKPlace | J3: Web + APP 2025 | K3: Web + APP 2026 | L3: Afiliados 2025 | M3: Afiliados 2026 | N3: TMK 2025 | O3: TMK 2026 | P3: WA 2025 | Q3: WA 2026 | R3: Ent. en Tienda 2025 | S3: Ent. en Tienda 2026 | T3: Meli Drop 2025 | U3: Meli Drop 2026 | V3: Meli Full 2025 | W3: Meli Full 2026 | X3: Amazon Drop 2025 | Y3: Amazon Drop 2026 | Z3: Amazon Full 2025 | AA3: Amazon Full 2026 | AB3: TikTok 2025 | AC3: TikTok 2026 | AD3: Shein 2025 | AE3: Shein 2026 | AF3: Venta Total 2026 | AG3: Alcance vs Meta | AH3: Deuda | AI3: Crecimiento | AJ3: Share vs Global 2025 | AK3: Share vs Global 2026 | AL3: Global YoY | AO3: Fecha | AP3: Digital 2025 | AQ3: MKP 2025 | AR3: Real Digital 2026 | AS3: Real MKP 2026 | AT3: YoY Digital | AU3: YoY Mktp | AV3: Meta Digital | AW3: Meta Mktp | AX3: Cump Digital | AY3: Cump Mktp | AZ3: Cump Total | BA3: Share Mktp | BB3: Share dig | BC3: Deuda Digital | BD3: Deuda Mktp | BE3: Digital vs25 | BF3: MKP vs25
A4: 45659 | B4: 35585285 | C4: =+J4+L4+N4+P4+R4+T4+V4+X4+Z4+AB4+AD4 -> 3530236.3 | D4: =+Tabla22[[#This Row],[Share diario]] -> -0.00033795059 | E4: =+Tabla22[[#This Row],[Global 2026]] -> 1767787 | F4: 46023 | G4: =+H4+I4 -> -36578.828 | H4: -91461.011 | I4: 54882.183 | J4: 2533552 | K4: 1117875 | L4: 48254.31 | M4: 17319 | N4: 21696 | O4: 0 | P4: 5984 | Q4: 1884 | R4: 47691 | S4: 0 | T4: 671816 | U4: 511381 | V4: 116771 | W4: 78269 | X4: 84472 | Y4: 31357 | Z4: 0 | AA4: 7591 | AB4: 0 | AC4: 2016 | AD4: 0 | AE4: 0 | AF4: =+AE4+AC4+AA4+Y4+W4+U4+S4+Q4+O4+M4+K4 -> 1767692 | AG4: =+AF4/G4 -> -48.325551 | AH4: =+AF4-G4 -> 1804270.8 | AI4: =+AF4/C4-1 -> -0.49927091 | AJ4: =+C4/B4 -> 0.099204947 | AK4: =+AF4/E4 -> 0.99994626 | AL4: =+E4/B4-1 -> -0.95032253 | AO4: =+F4 -> 46023 | AP4: =Tabla2[[#This Row],[Web + APP 2025]]+Tabla2[[#This Row],[Afiliados 2025]]+Tabla2[[#This Row],[TMK 2025]]+Tabla2[[#This Row],[WA 2025]]+Tabla2[[#This Row],[Ent. en Tienda 2025]] -> 2657177.3 | AQ4: =Tabla2[[#This Row],[Meli Drop 2025]]+Tabla2[[#This Row],[Meli Full 2025]]+Tabla2[[#This Row],[Amazon Drop 2025]]+Tabla2[[#This Row],[Amazon Full 2025]]+Tabla2[[#This Row],[TikTok 2025]]+Tabla2[[#This Row],[Shein 2025]] -> 873059 | AR4: =Tabla2[[#This Row],[Web + APP 2026]]+Tabla2[[#This Row],[Afiliados 2026]]+Tabla2[[#This Row],[TMK 2026]]+Tabla2[[#This Row],[WA 2026]]+Tabla2[[#This Row],[Ent. en Tienda 2026]] -> 1137078 | AS4: =Tabla2[[#This Row],[Meli Drop 2026]]+Tabla2[[#This Row],[Meli Full 2026]]+Tabla2[[#This Row],[Amazon Drop 2026]]+Tabla2[[#This Row],[Amazon Full 2026]]+Tabla2[[#This Row],[TikTok 2026]]+Tabla2[[#This Row],[Shein 2026]] -> 630614 | AT4: =+AR4/AP4-1 -> -0.57207297 | AU4: =+AS4/AQ4-1 -> -0.27769601 | AV4: =+H4 -> -91461.011 | AW4: =+I4 -> 54882.183 | AX4: =+AR4/AV4 -> -12.432379 | AY4: =+AS4/AW4 -> 11.490323 | AZ4: =+(AR4+AS4)/(AV4+AW4) -> -48.325551 | BA4: 0.0024610845 | BB4: -0.001042448 | BC4: =+AR4-AV4 -> 1228539 | BD4: =+AS4-AW4 -> 575731.82
A5: 45660 | B5: 45059441 | C5: =+J5+L5+N5+P5+R5+T5+V5+X5+Z5+AB5+AD5 -> 2122251.3 | D5: =+Tabla22[[#This Row],[Share diario]] -> 0.040988265 | E5: =+Tabla22[[#This Row],[Global 2026]] -> 37878399 | F5: 46024 | G5: =+H5+I5 -> 4512263.3 | H5: 3388096 | I5: 1124167.3 | J5: 1249824 | K5: 1824628 | L5: 33610.345 | M5: =20000+12072 -> 32072 | N5: 21922 | O5: 15461 | P5: 4267 | Q5: 5339 | R5: 40797 | S5: 100874 | T5: 650641 | U5: 906403 | V5: 73651 | W5: 134485 | X5: 47539 | Y5: 28403 | Z5: 0 | AA5: 8334 | AB5: 0 | AC5: 1412 | AD5: 0 | AE5: 0 | AF5: =+AE5+AC5+AA5+Y5+W5+U5+S5+Q5+O5+M5+K5 -> 3057411 | AG5: =+AF5/G5 -> 0.67757815 | AH5: =+AF5-G5 -> -1454852.3 | AI5: =+AF5/C5-1 -> 0.4406451 | AJ5: =+C5/B5 -> 0.047098927 | AK5: =+AF5/E5 -> 0.080716479 | AL5: =+E5/B5-1 -> -0.1593682 | AO5: =+F5 -> 46024 | AP5: =Tabla2[[#This Row],[Web + APP 2025]]+Tabla2[[#This Row],[Afiliados 2025]]+Tabla2[[#This Row],[TMK 2025]]+Tabla2[[#This Row],[WA 2025]]+Tabla2[[#This Row],[Ent. en Tienda 2025]] -> 1350420.3 | AQ5: =Tabla2[[#This Row],[Meli Drop 2025]]+Tabla2[[#This Row],[Meli Full 2025]]+Tabla2[[#This Row],[Amazon Drop 2025]]+Tabla2[[#This Row],[Amazon Full 2025]]+Tabla2[[#This Row],[TikTok 2025]]+Tabla2[[#This Row],[Shein 2025]] -> 771831 | AR5: =Tabla2[[#This Row],[Web + APP 2026]]+Tabla2[[#This Row],[Afiliados 2026]]+Tabla2[[#This Row],[TMK 2026]]+Tabla2[[#This Row],[WA 2026]]+Tabla2[[#This Row],[Ent. en Tienda 2026]] -> 1978374 | AS5: =Tabla2[[#This Row],[Meli Drop 2026]]+Tabla2[[#This Row],[Meli Full 2026]]+Tabla2[[#This Row],[Amazon Drop 2026]]+Tabla2[[#This Row],[Amazon Full 2026]]+Tabla2[[#This Row],[TikTok 2026]]+Tabla2[[#This Row],[Shein 2026]] -> 1079037 | AT5: =+AR5/AP5-1 -> 0.46500607 | AU5: =+AS5/AQ5-1 -> 0.39802236 | AV5: =+H5 -> 3388096 | AW5: =+I5 -> 1124167.3 | AX5: =+AR5/AV5 -> 0.58391912 | AY5: =+AS5/AW5 -> 0.95985444 | AZ5: =+(AR5+AS5)/(AV5+AW5) -> 0.67757815 | BA5: 0.050411091 | BB5: 0.038616606 | BC5: =+AR5-AV5 -> -1409722 | BD5: =+AS5-AW5 -> -45130.332
